Workbook

Sheet Table
A1: cliente_codigo | B1: zona_codigo | C1: Domingo | D1: fechaAnclaje | E1: frecuencia | F1: Jueves | G1: Lunes | H1: Martes | I1: Miercoles | J1: Orden_Visita | K1: Orden_Domingo | L1: Orden_Jueves | M1: Orden_Lunes | N1: Orden_Martes | O1: Orden_Miercoles | P1: Orden_Sabado | Q1: Orden_Viernes | R1: Sabado | S1: semanaInicial | T1: Viernes | U1: vendedor | V1: dia
A2: -1 | B2: 99 | C2: 0 | D2: 8 | E2: 1 | F2: 0 | G2: 0 | H2: 0 | I2: 0 | J2: 9999 | K2: 0 | L2: 0 | M2: 0 | N2: 0 | O2: 0 | P2: 0 | Q2: 0 | R2: 0 | S2: 1 | T2: 0 | U2: =+LEFT(B2,2) -> 99 | V2: 9
A3: 1 | B3: 902 | C3: 0 | D3: 45658 | E3: 1 | F3: 0 | G3: 0 | H3: 0 | I3: 0 | J3: 9999 | K3: 0 | L3: 0 | M3: 0 | N3: 0 | O3: 0 | P3: 0 | Q3: 0 | R3: 0 | S3: 1 | T3: 0 | U3: =+LEFT(B3,2) -> 90 | V3: 2
A4: 2 | B4: 902 | C4: 0 | D4: 45658 | E4: 1 | F4: 100 | G4: 100 | H4: 100 | I4: 100 | J4: 9999 | K4: 0 | L4: 0 | M4: 0 | N4: 0 | O4: 0 | P4: 0 | Q4: 0 | R4: 0 | S4: 0 | T4: 100 | U4: =+LEFT(B4,2) -> 90 | V4: 2
A5: 3 | B5: 343 | C5: 0 | D5: 45658 | E5: 1 | F5: 0 | G5: 0 | H5: 0 | I5: 34 | J5: 9999 | K5: 9999 | L5: 9999 | M5: 9999 | N5: 9999 | O5: 9999 | P5: 9999 | Q5: 9999 | R5: 0 | S5: 0 | T5: 0 | U5: =+LEFT(B5,2) -> 34 | V5: 3
A6: 4 | B6: 342 | C6: 0 | D6: 45658 | E6: 1 | F6: 0 | G6: 0 | H6: 34 | I6: 0 | J6: 9999 | K6: 9999 | L6: 9999 | M6: 9999 | N6: 9999 | O6: 9999 | P6: 9999 | Q6: 9999 | R6: 0 | S6: 0 | T6: 0 | U6: =+LEFT(B6,2) -> 34 | V6: 2
A7: 5 | B7: 342 | C7: 0 | D7: 45658 | E7: 1 | F7: 0 | G7: 0 | H7: 34 | I7: 0 | J7: 9999 | K7: 9999 | L7: 9999 | M7: 9999 | N7: 9999 | O7: 9999 | P7: 9999 | Q7: 9999 | R7: 0 | S7: 0 | T7: 0 | U7: =+LEFT(B7,2) -> 34 | V7: 2
A8: 6 | B8: 342 | C8: 0 | D8: 45658 | E8: 1 | F8: 0 | G8: 0 | H8: 34 | I8: 0 | J8: 9999 | K8: 9999 | L8: 9999 | M8: 9999 | N8: 9999 | O8: 9999 | P8: 9999 | Q8: 9999 | R8: 0 | S8: 0 | T8: 0 | U8: =+LEFT(B8,2) -> 34 | V8: 2
A9: 7 | B9: 333 | C9: 0 | D9: 2 | E9: 1 | F9: 0 | G9: 0 | H9: 0 | I9: 33 | J9: 9999 | K9: 9999 | L9: 9999 | M9: 9999 | N9: 9999 | O9: 9999 | P9: 9999 | Q9: 9999 | R9: 0 | S9: 1 | T9: 0 | U9: =+LEFT(B9,2) -> 33 | V9: 3
A10: 7 | B10: 342 | C10: 0 | E10: 1 | F10: 0 | G10: 0 | H10: 34 | I10: 0 | J10: 9999 | K10: 9999 | L10: 9999 | M10: 9999 | N10: 9999 | O10: 9999 | P10: 9999 | Q10: 9999 | R10: 0 | S10: 1 | T10: 0 | U10: =+LEFT(B10,2) -> 34 | V10: 2
A11: 8 | B11: 342 | C11: 0 | D11: 45658 | E11: 1 | F11: 0 | G11: 0 | H11: 34 | I11: 0 | J11: 9999 | K11: 9999 | L11: 9999 | M11: 9999 | N11: 9999 | O11: 9999 | P11: 9999 | Q11: 9999 | R11: 0 | S11: 0 | T11: 0 | U11: =+LEFT(B11,2) -> 34 | V11: 2
A12: 9 | B12: 342 | C12: 0 | D12: 45658 | E12: 1 | F12: 0 | G12: 0 | H12: 34 | I12: 0 | J12: 9999 | K12: 9999 | L12: 9999 | M12: 9999 | N12: 9999 | O12: 9999 | P12: 9999 | Q12: 9999 | R12: 0 | S12: 0 | T12: 0 | U12: =+LEFT(B12,2) -> 34 | V12: 2
A13: 10 | B13: 342 | C13: 0 | D13: 45658 | E13: 1 | F13: 0 | G13: 0 | H13: 34 | I13: 0 | J13: 9999 | K13: 9999 | L13: 9999 | M13: 9999 | N13: 9999 | O13: 9999 | P13: 9999 | Q13: 9999 | R13: 0 | S13: 0 | T13: 0 | U13: =+LEFT(B13,2) -> 34 | V13: 2
A14: 11 | B14: 342 | C14: 0 | D14: 45658 | E14: 1 | F14: 0 | G14: 0 | H14: 34 | I14: 0 | J14: 9999 | K14: 9999 | L14: 9999 | M14: 9999 | N14: 9999 | O14: 9999 | P14: 9999 | Q14: 9999 | R14: 0 | S14: 0 | T14: 0 | U14: =+LEFT(B14,2) -> 34 | V14: 2
A15: 12 | B15: 353 | C15: 0 | D15: 45658 | E15: 1 | F15: 0 | G15: 0 | H15: 0 | I15: 35 | J15: 9999 | K15: 9999 | L15: 9999 | M15: 9999 | N15: 9999 | O15: 9999 | P15: 9999 | Q15: 9999 | R15: 0 | S15: 0 | T15: 0 | U15: =+LEFT(B15,2) -> 35 | V15: 3
A16: 13 | B16: 353 | C16: 0 | D16: 45658 | E16: 1 | F16: 0 | G16: 0 | H16: 0 | I16: 35 | J16: 9999 | K16: 9999 | L16: 9999 | M16: 9999 | N16: 9999 | O16: 9999 | P16: 9999 | Q16: 9999 | R16: 0 | S16: 0 | T16: 0 | U16: =+LEFT(B16,2) -> 35 | V16: 3
A17: 14 | B17: 353 | C17: 0 | D17: 45658 | E17: 1 | F17: 0 | G17: 0 | H17: 0 | I17: 35 | J17: 9999 | K17: 9999 | L17: 9999 | M17: 9999 | N17: 9999 | O17: 9999 | P17: 9999 | Q17: 9999 | R17: 0 | S17: 0 | T17: 0 | U17: =+LEFT(B17,2) -> 35 | V17: 3
A18: 15 | B18: 353 | C18: 0 | D18: 45658 | E18: 1 | F18: 0 | G18: 0 | H18: 0 | I18: 35 | J18: 9999 | K18: 9999 | L18: 9999 | M18: 9999 | N18: 9999 | O18: 9999 | P18: 9999 | Q18: 9999 | R18: 0 | S18: 0 | T18: 0 | U18: =+LEFT(B18,2) -> 35 | V18: 3
A19: 16 | B19: 353 | C19: 0 | D19: 45658 | E19: 1 | F19: 0 | G19: 0 | H19: 0 | I19: 35 | J19: 9999 | K19: 9999 | L19: 9999 | M19: 9999 | N19: 9999 | O19: 9999 | P19: 9999 | Q19: 9999 | R19: 0 | S19: 0 | T19: 0 | U19: =+LEFT(B19,2) -> 35 | V19: 3
A20: 17 | B20: 353 | C20: 0 | D20: 45658 | E20: 1 | F20: 0 | G20: 0 | H20: 0 | I20: 35 | J20: 9999 | K20: 9999 | L20: 9999 | M20: 9999 | N20: 9999 | O20: 9999 | P20: 9999 | Q20: 9999 | R20: 0 | S20: 0 | T20: 0 | U20: =+LEFT(B20,2) -> 35 | V20: 3
A21: 18 | B21: 353 | C21: 0 | D21: 45658 | E21: 1 | F21: 0 | G21: 0 | H21: 0 | I21: 35 | J21: 9999 | K21: 9999 | L21: 9999 | M21: 9999 | N21: 9999 | O21: 9999 | P21: 9999 | Q21: 9999 | R21: 0 | S21: 0 | T21: 0 | U21: =+LEFT(B21,2) -> 35 | V21: 3
A22: 19 | B22: 343 | C22: 0 | D22: 45658 | E22: 1 | F22: 0 | G22: 0 | H22: 0 | I22: 34 | J22: 9999 | K22: 9999 | L22: 9999 | M22: 9999 | N22: 9999 | O22: 9999 | P22: 9999 | Q22: 9999 | R22: 0 | S22: 0 | T22: 0 | U22: =+LEFT(B22,2) -> 34 | V22: 3
... A27: 24 | B27: 343 | C27: 0 | D27: 45658 | E27: 1 | F27: 0 | G27: 0 | H27: 0 | I27: 34 | J27: 9999 | K27: 9999 | L27: 9999 | M27: 9999 | N27: 9999 | O27: 9999 | P27: 9999 | Q27: 9999 | R27: 0 | S27: 0 | T27: 0 | U27: =+LEFT(B27,2) -> 34 | V27: 3
A28: 25 | B28: 341 | C28: 0 | D28: 45658 | E28: 1 | F28: 0 | G28: 34 | H28: 0 | I28: 0 | J28: 9999 | K28: 9999 | L28: 9999 | M28: 9999 | N28: 9999 | O28: 9999 | P28: 9999 | Q28: 9999 | R28: 0 | S28: 0 | T28: 0 | U28: =+LEFT(B28,2) -> 34 | V28: lunes
A29: 26 | B29: 344 | C29: 0 | D29: 45658 | E29: 1 | F29: 34 | G29: 0 | H29: 0 | I29: 0 | J29: 9999 | K29: 9999 | L29: 9999 | M29: 9999 | N29: 9999 | O29: 9999 | P29: 9999 | Q29: 9999 | R29: 0 | S29: 0 | T29: 0 | U29: =+LEFT(B29,2) -> 34 | V29: 4
A30: 27 | B30: 344 | C30: 0 | D30: 45658 | E30: 1 | F30: 34 | G30: 0 | H30: 0 | I30: 0 | J30: 9999 | K30: 9999 | L30: 9999 | M30: 9999 | N30: 9999 | O30: 9999 | P30: 9999 | Q30: 9999 | R30: 0 | S30: 0 | T30: 0 | U30: =+LEFT(B30,2) -> 34 | V30: 4
A31: 28 | B31: 344 | C31: 0 | D31: 45658 | E31: 1 | F31: 34 | G31: 0 | H31: 0 | I31: 0 | J31: 9999 | K31: 9999 | L31: 9999 | M31: 9999 | N31: 9999 | O31: 9999 | P31: 9999 | Q31: 9999 | R31: 0 | S31: 0 | T31: 0 | U31: =+LEFT(B31,2) -> 34 | V31: 4
A32: 29 | B32: 343 | C32: 0 | D32: 45658 | E32: 1 | F32: 0 | G32: 0 | H32: 0 | I32: 34 | J32: 9999 | K32: 9999 | L32: 9999 | M32: 9999 | N32: 9999 | O32: 9999 | P32: 9999 | Q32: 9999 | R32: 0 | S32: 0 | T32: 0 | U32: =+LEFT(B32,2) -> 34 | V32: 3
A33: 30 | B33: 344 | C33: 0 | D33: 45658 | E33: 1 | F33: 34 | G33: 0 | H33: 0 | I33: 0 | J33: 9999 | K33: 9999 | L33: 9999 | M33: 9999 | N33: 9999 | O33: 9999 | P33: 9999 | Q33: 9999 | R33: 0 | S33: 0 | T33: 0 | U33: =+LEFT(B33,2) -> 34 | V33: 4
A34: 31 | B34: 344 | C34: 0 | D34: 45658 | E34: 1 | F34: 34 | G34: 0 | H34: 0 | I34: 0 | J34: 9999 | K34: 9999 | L34: 9999 | M34: 9999 | N34: 9999 | O34: 9999 | P34: 9999 | Q34: 9999 | R34: 0 | S34: 0 | T34: 0 | U34: =+LEFT(B34,2) -> 34 | V34: 4
A35: 32 | B35: 343 | C35: 0 | D35: 45658 | E35: 1 | F35: 0 | G35: 0 | H35: 0 | I35: 34 | J35: 9999 | K35: 9999 | L35: 9999 | M35: 9999 | N35: 9999 | O35: 9999 | P35: 9999 | Q35: 9999 | R35: 0 | S35: 0 | T35: 0 | U35: =+LEFT(B35,2) -> 34 | V35: 3
A36: 33 | B36: 343 | C36: 0 | D36: 45658 | E36: 1 | F36: 0 | G36: 0 | H36: 0 | I36: 34 | J36: 9999 | K36: 9999 | L36: 9999 | M36: 9999 | N36: 9999 | O36: 9999 | P36: 9999 | Q36: 9999 | R36: 0 | S36: 0 | T36: 0 | U36: =+LEFT(B36,2) -> 34 | V36: 3
A37: 34 | B37: 343 | C37: 0 | D37: 45658 | E37: 1 | F37: 0 | G37: 0 | H37: 0 | I37: 34 | J37: 9999 | K37: 9999 | L37: 9999 | M37: 9999 | N37: 9999 | O37: 9999 | P37: 9999 | Q37: 9999 | R37: 0 | S37: 0 | T37: 0 | U37: =+LEFT(B37,2) -> 34 | V37: 3
A38: 35 | B38: 344 | C38: 0 | D38: 45658 | E38: 1 | F38: 34 | G38: 0 | H38: 0 | I38: 0 | J38: 9999 | K38: 9999 | L38: 9999 | M38: 9999 | N38: 9999 | O38: 9999 | P38: 9999 | Q38: 9999 | R38: 0 | S38: 0 | T38: 0 | U38: =+LEFT(B38,2) -> 34 | V38: 4
A39: 36 | B39: 343 | C39: 0 | D39: 45658 | E39: 1 | F39: 0 | G39: 0 | H39: 0 | I39: 34 | J39: 9999 | K39: 9999 | L39: 9999 | M39: 9999 | N39: 9999 | O39: 9999 | P39: 9999 | Q39: 9999 | R39: 0 | S39: 0 | T39: 0 | U39: =+LEFT(B39,2) -> 34 | V39: 3
A40: 37 | B40: 343 | C40: 0 | D40: 45658 | E40: 1 | F40: 0 | G40: 0 | H40: 0 | I40: 34 | J40: 9999 | K40: 9999 | L40: 9999 | M40: 9999 | N40: 9999 | O40: 9999 | P40: 9999 | Q40: 9999 | R40: 0 | S40: 1 | T40: 0 | U40: =+LEFT(B40,2) -> 34 | V40: 3
... A47: 44 | B47: 344 | C47: 0 | D47: 45658 | E47: 1 | F47: 34 | G47: 0 | H47: 0 | I47: 0 | J47: 9999 | K47: 9999 | L47: 9999 | M47: 9999 | N47: 9999 | O47: 9999 | P47: 9999 | Q47: 9999 | R47: 0 | S47: 0 | T47: 0 | U47: =+LEFT(B47,2) -> 34 | V47: 4
A48: 45 | B48: 451 | C48: 0 | D48: 2 | E48: 1 | F48: 0 | G48: 45 | H48: 0 | I48: 0 | J48: 9999 | K48: 9999 | L48: 9999 | M48: 9999 | N48: 9999 | O48: 9999 | P48: 9999 | Q48: 9999 | R48: 0 | S48: 1 | T48: 0 | U48: =+LEFT(B48,2) -> 45 | V48: lunes
A49: 46 | B49: 343 | C49: 0 | D49: 45658 | E49: 1 | F49: 0 | G49: 0 | H49: 0 | I49: 34 | J49: 9999 | K49: 9999 | L49: 9999 | M49: 9999 | N49: 9999 | O49: 9999 | P49: 9999 | Q49: 9999 | R49: 0 | S49: 0 | T49: 0 | U49: =+LEFT(B49,2) -> 34 | V49: 3
A50: 47 | B50: 344 | C50: 0 | D50: 45658 | E50: 1 | F50: 34 | G50: 0 | H50: 0 | I50: 0 | J50: 9999 | K50: 9999 | L50: 9999 | M50: 9999 | N50: 9999 | O50: 9999 | P50: 9999 | Q50: 9999 | R50: 0 | S50: 0 | T50: 0 | U50: =+LEFT(B50,2) -> 34 | V50: 4
...

Sheet Hoja1
A1: Cliente | B1: dia
A2: 228 | B2: =+VLOOKUP(A2,Table!A:V,22,0) -> 4
A3: 971 | B3: =+VLOOKUP(A3,Table!A:V,22,0) -> 6
A4: 1292 | B4: =+VLOOKUP(A4,Table!A:V,22,0) -> 5
A5: 1303 | B5: =+VLOOKUP(A5,Table!A:V,22,0) -> 3
A6: 1637 | B6: =+VLOOKUP(A6,Table!A:V,22,0) -> 2
A7: 1660 | B7: =+VLOOKUP(A7,Table!A:V,22,0) -> 3
A8: 2185 | B8: =+VLOOKUP(A8,Table!A:V,22,0) -> 2
A9: 2193 | B9: =+VLOOKUP(A9,Table!A:V,22,0) -> lunes
A10: 2259 | B10: =+VLOOKUP(A10,Table!A:V,22,0) -> 2
A11: 2329 | B11: =+VLOOKUP(A11,Table!A:V,22,0) -> 5
A12: 2347 | B12: =+VLOOKUP(A12,Table!A:V,22,0) -> 5
A13: 2348 | B13: =+VLOOKUP(A13,Table!A:V,22,0) -> 3
... A3664: 39612912 | B3664: =+VLOOKUP(A3664,Table!A:V,22,0) -> 2
